Workbook

Sheet Lisez-moi
A1: Catalogue des sources open data – Portail territorial (commune / canton / EPCI)
A2: Périmètre de cette version : 5 catégories sur les 16 cibles. Structure et nomenclature figées pour permettre l'ajout des 12 autres sans reprise du modèle.
A4: 1. À quoi sert ce document
A5: Il recense, pour chaque donnée envisagée, la source publique réelle, la maille à laquelle elle est effectivement publiée, et la possibilité ou non de la restituer aux 3 niveaux du site.
A6: Il sert de base au tri : une ligne dont les 3 colonnes de niveau sont à « Non » ou « Partiel » est candidate à l'abandon ou à un affichage dégradé.
A7: Il alimente directement la table « indicateur » de la base : une ligne du catalogue = un enregistrement.
A9: 2. Règle retenue (validée) : on n'affiche que l'existant et le pertinent
A10: Aucune valeur n'est reconstituée par approximation. Si un indicateur n'existe pas à un niveau, il n'apparaît pas dans l'interface de ce niveau.
A11: Conséquence à assumer côté UI : le nombre de fiches varie d'un niveau à l'autre. La fiche « canton » sera nettement plus courte que la fiche « commune ». C'est un choix de justesse, pas un défaut.
A12: Conséquence côté modèle : la disponibilité par niveau est une propriété de l'indicateur, stockée en base, et non une règle codée en dur dans le front.
A14: 3. Les quatre modes d'obtention d'une valeur
A15: Natif — la source publie déjà la valeur à ce niveau. Aucun calcul. C'est le cas idéal.
... A40: Mise à jour du 07/09/2026 : ajout de la colonne « Implanté », et de treize données mises en service depuis la version initiale — eau potable, sécheresse, nappes, rivières, risques, vigilance, agriculture biologique, écoles, équipements, élus, équipements hivernaux.

Sheet Catalogue
A1: ID | B1: Catégorie | C1: Donnée (libellé site) | D1: Producteur | E1: Jeu de données / source | F1: Accès technique | G1: Maille native | H1: Commune | I1: Canton | J1: EPCI | K1: Règle d'agrégation | L1: Fréquence | M1: Millésime (indicatif) | N1: Affichage recommandé | O1: Licence | P1: Passage à l'échelle | Q1: Pièges / remarques | R1: Implanté
A2: POP-01 | B2: Population & démographie | C2: Population par commune | D2: INSEE | E2: Populations légales (recensement) | F2: Fichier CSV / API INSEE | G2: Commune | H2: Natif | I2: Reconstitué | J2: Agrégeable | K2: Somme des effectifs | L2: Annuelle | M2: Millésime N-3 | N2: Texte + carte choroplèthe | O2: LO 2.0 | P2: National | Q2: Distinguer population municipale et population totale : ne pas mélanger les deux dans une même série. | R2: oui — 01/03
A3: POP-02 | B3: Population & démographie | C3: Population par âge | D3: INSEE | E3: Recensement – base Population (POP1B) | F3: Fichier CSV | G3: Commune | H3: Natif | I3: Reconstitué | J3: Agrégeable | K3: Somme par tranche d'âge | L3: Annuelle | M3: Millésime N-3 | N3: Pyramide des âges + tableau | O3: LO 2.0 | P3: National | Q3: Choisir une seule fois le découpage de tranches et s'y tenir pour toutes les catégories. | R3: oui — 11
A4: POP-03 | B4: Population & démographie | C4: Répartition par sexe | D4: INSEE | E4: Recensement – base Population (POP1B) | F4: Fichier CSV | G4: Commune | H4: Natif | I4: Reconstitué | J4: Agrégeable | K4: Somme par sexe | L4: Annuelle | M4: Millésime N-3 | N4: Graphique + texte | O4: LO 2.0 | P4: National | Q4: Même fichier source que POP-02 : un seul chargement pour les deux indicateurs. | R4: oui — 11
A5: POP-04 | B5: Population & démographie | C5: Naissances | D5: INSEE | E5: État civil – naissances domiciliées | F5: Fichier CSV | G5: Commune | H5: Natif | I5: Reconstitué | J5: Agrégeable | K5: Somme | L5: Annuelle | M5: Année N-2 | N5: Courbe + texte | O5: LO 2.0 | P5: National | Q5: Domiciliées (commune de résidence de la mère) et non lieu d'accouchement : ne jamais lire comme une activité de maternité.
A6: POP-05 | B6: Population & démographie | C6: Décès | D6: INSEE | E6: État civil / fichier des personnes décédées | F6: Fichier CSV mensuel | G6: Commune | H6: Natif | I6: Reconstitué | J6: Agrégeable | K6: Somme | L6: Mensuelle et annuelle | M6: Année en cours | N6: Courbe + texte | O6: LO 2.0 | P6: National | Q6: Le fichier des décès contient des données nominatives : n'exposer que des agrégats, jamais la ligne individuelle.
A7: POP-06 | B7: Population & démographie | C7: Espérance de vie | D7: INSEE | E7: Statistiques d'état civil / tables de mortalité | F7: Fichier CSV | G7: Département | H7: Non | I7: Non | J7: Non | K7: Non calculable | L7: Annuelle | M7: Année N-1 | N7: Texte (contexte départemental) | O7: LO 2.0 | P7: National | Q7: Aucune maille infra-départementale robuste. À écarter des 3 niveaux, ou afficher en repère de contexte clairement étiqueté « département ». | R7: hors périmètre
A8: POP-07 | B8: Population & démographie | C8: Migrations résidentielles | D8: INSEE | E8: Recensement – mobilités résidentielles (MIGCOM) | F8: Fichier CSV volumineux | G8: Commune (flux) | H8: Natif | I8: Non | J8: Agrégeable | K8: Somme des flux, hors flux internes | L8: Annuelle | M8: Millésime N-3 | N8: Carte de flux + tableau | O8: LO 2.0 | P8: National | Q8: En agrégeant à l'EPCI, les flux entre communes du même EPCI deviennent internes et doivent être neutralisés.
A9: POP-08 | B9: Population & démographie | C9: Ménages | D9: INSEE | E9: Recensement – base Logement / Ménages | F9: Fichier CSV | G9: Commune | H9: Natif | I9: Reconstitué | J9: Agrégeable | K9: Somme ; taille moyenne recalculée | L9: Annuelle | M9: Millésime N-3 | N9: Tableau + graphique | O9: LO 2.0 | P9: National | Q9: La taille moyenne des ménages est un ratio : la recalculer, ne jamais la moyenner. | R9: oui — 11
A10: POP-09 | B10: Population & démographie | C10: Familles | D10: INSEE | E10: Recensement – base Couples-Familles-Ménages | F10: Fichier CSV | G10: Commune | H10: Natif | I10: Reconstitué | J10: Agrégeable | K10: Somme par type de famille | L10: Annuelle | M10: Millésime N-3 | N10: Tableau | O10: LO 2.0 | P10: National | Q10: Nomenclature de types de familles à figer dès le départ. | R10: oui — 11
A11: POP-10 | B11: Population & démographie | C11: Densité de population | D11: Calculé | E11: INSEE (population) + IGN Admin Express (superficie) | F11: Calcul interne | G11: Commune | H11: Recalculé | I11: Recalculé | J11: Recalculé | K11: Population agrégée / superficie agrégée | L11: Annuelle | M11: Aligné sur POP-01 | N11: Carte choroplèthe | O11: LO 2.0 | P11: National | Q11: Indicateur calculé, pas téléchargé. Fixer la source de superficie une fois pour toutes (cadastrale ≠ géographique). | R11: oui — 03
A12: POP-11 | B12: Population & démographie | C12: Grille de densité / typologie communale | D12: INSEE | E12: Grille communale de densité | F12: Fichier CSV | G12: Commune | H12: Natif | I12: Non | J12: Non | K12: Non agrégeable (typologie) | L12: Révision pluriannuelle | M12: Version en vigueur | N12: Carte catégorielle | O12: LO 2.0 | P12: National | Q12: Classement qualitatif : ne pas tenter de moyenne. Utile pour contextualiser une commune.
A13: POP-12 | B13: Population & démographie | C13: Projections démographiques | D13: INSEE | E13: Modèle Omphale | F13: Fichier CSV | G13: Département / zones d'étude | H13: Non | I13: Non | J13: Partiel | K13: Non calculable | L13: Pluriannuelle | M13: Exercice en vigueur | N13: Courbe (contexte) | O13: LO 2.0 | P13: National | Q13: Pas de projection communale. À écarter aux 3 niveaux, sauf si un EPCI a fait l'objet d'une commande spécifique. | R13: hors périmètre
A14: POP-13 | B14: Population & démographie | C14: Revenus (médiane, déciles) | D14: INSEE | E14: Filosofi – revenus localisés | F14: Fichier CSV | G14: Commune | H14: Partiel | I14: Non | J14: Natif | K14: Non calculable (médiane) | L14: Annuelle | M14: Millésime N-3 | N14: Texte + comparatif | O14: LO 2.0 | P14: National | Q14: Non diffusé pour les petites communes (secret statistique). Filosofi publie nativement à l'EPCI : privilégier ce niveau.
A15: POP-14 | B15: Population & démographie | C15: Taux de pauvreté | D15: INSEE | E15: Filosofi | F15: Fichier CSV | G15: Commune | H15: Partiel | I15: Non | J15: Natif | K15: Recalcul impossible sans effectifs | L15: Annuelle | M15: Millésime N-3 | N15: Texte + carte | O15: LO 2.0 | P15: National | Q15: Même restriction de diffusion que POP-13.
A16: POP-15 | B16: Population & démographie | C16: Inégalités (rapport interdécile, Gini) | D16: INSEE | E16: Filosofi | F16: Fichier CSV | G16: Commune | H16: Partiel | I16: Non | J16: Natif | K16: Non calculable | L16: Annuelle | M16: Millésime N-3 | N16: Texte | O16: LO 2.0 | P16: National | Q16: Indices non agrégeables par construction. Reprendre la valeur publiée ou ne rien afficher.
A17: POP-16 | B17: Population & démographie | C17: Recensement (séries historiques) | D17: INSEE | E17: Séries historiques de population | F17: Fichier CSV | G17: Commune | H17: Natif | I17: Reconstitué | J17: Agrégeable | K17: Somme | L17: Annuelle | M17: Séries longues | N17: Courbe d'évolution | O17: LO 2.0 | P17: National | Q17: Les fusions de communes cassent les séries : appliquer une table de passage COG avant tout graphique d'évolution.
A18: GEO-01 | B18: Géographie & cartographie | C18: Coordonnées géographiques du territoire | D18: IGN / INSEE | E18: Admin Express + Code Officiel Géographique | F18: WFS Géoplateforme / fichier | G18: Commune | H18: Natif | I18: Natif | J18: Natif | K18: Centroïde recalculé | L18: Annuelle | M18: Millésime courant | N18: Carte | O18: LO 2.0 | P18: National | Q18: Le centroïde géométrique peut tomber hors du territoire (communes concaves) : préférer un point de placement ou le chef-lieu. | R18: oui — 01
A19: GEO-02 | B19: Géographie & cartographie | C19: Référentiel des communes | D19: INSEE / Etalab | E19: Code Officiel Géographique, API Découpage administratif | F19: API REST | G19: Commune | H19: Natif | I19: Natif | J19: Natif | K19: Sans objet (référentiel) | L19: Annuelle (1er janvier) | M19: COG courant | N19: Tableau + recherche | O19: LO 2.0 | P19: National | Q19: Socle de tout le projet : c'est la table de référence à laquelle tout le reste se rattache. À charger en premier. | R19: oui — 01
A20: GEO-03 | B20: Géographie & cartographie | C20: Référentiel des intercommunalités | D20: DGCL / INSEE | E20: Banatic + COG | F20: Fichier / API | G20: EPCI | H20: Natif | I20: Sans objet | J20: Natif | K20: Sans objet (référentiel) | L20: Annuelle | M20: Millésime courant | N20: Tableau + carte | O20: LO 2.0 | P20: National | Q20: Recompositions fréquentes. Conserver l'historique de composition, sinon les agrégats passés deviennent non reproductibles. | R20: oui — 01
A21: GEO-04 | B21: Géographie & cartographie | C21: Limites administratives | D21: IGN | E21: Admin Express (commune, canton, EPCI, département) | F21: WFS Géoplateforme / téléchargement | G21: Toutes mailles | H21: Natif | I21: Natif | J21: Natif | K21: Sans objet (géométrie) | L21: Plusieurs fois par an | M21: Millésime courant | N21: Carte | O21: LO 2.0 | P21: National | Q21: Géométries lourdes : prévoir une version simplifiée pour l'affichage web et conserver la version précise pour les calculs. | R21: oui — 05
A22: GEO-05 | B22: Géographie & cartographie | C22: Parcelles cadastrales | D22: DGFiP / Etalab / IGN | E22: Cadastre (PCI vecteur), Parcellaire Express | F22: Téléchargement par commune / WFS | G22: Parcelle | H22: Natif | I22: Natif | J22: Natif | K22: Sans objet | L22: Trimestrielle | M22: Millésime courant | N22: Carte (zoom élevé uniquement) | O22: LO 2.0 | P22: Commune par commune | Q22: Volumétrie très importante. Ne charger qu'à la demande sur emprise réduite, jamais à l'échelle d'un EPCI.
A23: GEO-06 | B23: Géographie & cartographie | C23: Adresses | D23: IGN / Etalab | E23: Base Adresse Nationale (BAN) | F23: API adresse + fichiers par département | G23: Adresse | H23: Natif | I23: Natif | J23: Natif | K23: Comptage possible | L23: Quotidienne / continue | M23: Version courante | N23: Recherche + carte | O23: LO 2.0 | P23: National | Q23: Sert aussi de moteur de géocodage pour rattacher n'importe quel jeu de données à une commune.
A24: GEO-07 | B24: Géographie & cartographie | C24: Voies | D24: IGN / DGFiP | E24: BAN, BD TOPO, référentiel des voies | F24: API / WFS | G24: Voie | H24: Natif | I24: Natif | J24: Natif | K24: Comptage / linéaire | L24: Continue | M24: Version courante | N24: Carte + tableau | O24: LO 2.0 | P24: National | Q24: Le linéaire de voirie diffère selon la source (BD TOPO ≠ BAN) : choisir une source de référence et documenter le choix.
A25: GEO-08 | B25: Géographie & cartographie | C25: Codes postaux | D25: La Poste | E25: Base officielle des codes postaux | F25: Fichier CSV | G25: Code postal | H25: Partiel | I25: Non | J25: Non | K25: Non agrégeable | L25: Périodique | M25: Version courante | N25: Texte / recherche | O25: LO 2.0 | P25: National | Q25: Une commune peut porter plusieurs codes postaux et un code postal couvrir plusieurs communes. Attribut de recherche uniquement. | R25: oui — 01
A26: GEO-09 | B26: Géographie & cartographie | C26: Équipements publics géolocalisés | D26: INSEE | E26: Base Permanente des Équipements (BPE) | F26: Fichier CSV géolocalisé | G26: Équipement / commune | H26: Natif | I26: Reconstitué | J26: Agrégeable | K26: Comptage par type | L26: Annuelle | M26: Millésime N-1 | N26: Carte + tableau | O26: LO 2.0 | P26: National | Q26: Très transverse : alimente aussi Santé, Éducation, Culture, Services publics, Sport. Un seul chargement, plusieurs catégories. | R26: oui — 11 (BPE)
A27: GEO-10 | B27: Géographie & cartographie | C27: Données géographiques environnementales | D27: IGN / MTE / OFB | E27: Géoplateforme, INPN, zonages environnementaux | F27: WFS | G27: Zonage | H27: Natif | I27: Natif | J27: Natif | K27: Intersection géométrique | L27: Variable | M27: Variable | N27: Carte | O27: LO 2.0 | P27: National | Q27: Les zonages ne suivent pas les limites communales : calculer par intersection et afficher une surface, pas un booléen.
A28: GEO-11 | B28: Géographie & cartographie | C28: Référentiels géographiques socles | D28: IGN | E28: BD TOPO / Référentiel à Grande Échelle | F28: WFS / téléchargement | G28: Objet | H28: Natif | I28: Natif | J28: Natif | K28: Sans objet | L28: Plusieurs fois par an | M28: Millésime courant | N28: Carte | O28: LO 2.0 | P28: National | Q28: Fond technique commun à plusieurs catégories (transports, urbanisme, eau).
A29: GEO-12 | B29: Géographie & cartographie | C29: Fond de carte | D29: IGN / OSM | E29: Géoplateforme (data.geopf.fr) ou tuiles OpenStreetMap | F29: WMTS / TMS tuiles vectorielles | G29: Sans objet | H29: Natif | I29: Natif | J29: Natif | K29: Sans objet | L29: Continue | M29: Version courante | N29: Carte | O29: LO 2.0 / ODbL | P29: National | Q29: Ne pas taper les tuiles OSM communautaires en production. Géoplateforme ou tuiles auto-hébergées. Attribution obligatoire dans les deux cas. | R29: oui — 04
A30: TRA-01 | B30: Transports & mobilité | C30: Réseau routier | D30: IGN | E30: BD TOPO – tronçons de route | F30: WFS / téléchargement | G30: Tronçon | H30: Natif | I30: Natif | J30: Natif | K30: Linéaire par découpage | L30: Plusieurs fois par an | M30: Millésime courant | N30: Carte + linéaire en km | O30: LO 2.0 | P30: National | Q30: Le calcul de linéaire par territoire suppose de découper les tronçons sur les limites, pas de les compter en entier.
A31: TRA-02 | B31: Transports & mobilité | C31: Autoroutes et voies rapides | D31: IGN | E31: BD TOPO (attribut nature de la voie) | F31: WFS | G31: Tronçon | H31: Natif | I31: Natif | J31: Natif | K31: Linéaire par découpage | L31: Plusieurs fois par an | M31: Millésime courant | N31: Carte | O31: LO 2.0 | P31: National | Q31: Sous-ensemble filtré de TRA-01 : pas de chargement séparé.
A32: TRA-03 | B32: Transports & mobilité | C32: Accidents corporels de la route | D32: ONISR | E32: Bases annuelles des accidents corporels (BAAC) | F32: Fichiers CSV annuels | G32: Accident géolocalisé | H32: Agrégeable | I32: Agrégeable | J32: Agrégeable | K32: Comptage par appartenance géographique | L32: Annuelle | M32: Année N-1 | N32: Carte de points / chaleur + série | O32: LO 2.0 | P32: National | Q32: Qualité de géolocalisation inégale selon les années. Sur petite commune les effectifs sont faibles : éviter tout taux trompeur.
A33: TRA-04 | B33: Transports & mobilité | C33: Trafic routier (comptages) | D33: Cerema / DIR / collectivités | E33: Comptages routiers, publications locales | F33: Fichiers hétérogènes | G33: Point de comptage | H33: Partiel | I33: Partiel | J33: Partiel | K33: Non agrégeable | L33: Variable | M33: Variable | N33: Carte de points | O33: Variable | P33: Un flux par territoire | Q33: Couverture très inégale et formats non normalisés. Traiter comme donnée d'illustration ponctuelle, pas comme indicateur territorial.
A34: TRA-05 | B34: Transports & mobilité | C34: Offre de transport public | D34: Point d'Accès National (transport.data.gouv.fr) | E34: Jeux de données GTFS des autorités organisatrices | F34: Téléchargement GTFS | G34: Réseau / arrêt | H34: Natif | I34: Agrégeable | J34: Agrégeable | K34: Comptage d'arrêts et de lignes | L34: Variable selon l'AOM | M34: Version courante | N34: Carte + tableau | O34: LO 2.0 / ODbL | P34: Un flux par territoire | Q34: Un fichier par réseau, pas un fichier national : prévoir un connecteur par AOM du territoire couvert.
A35: TRA-06 | B35: Transports & mobilité | C35: Gares | D35: SNCF | E35: Référentiel des gares de voyageurs | F35: API / fichier | G35: Gare | H35: Natif | I35: Agrégeable | J35: Agrégeable | K35: Comptage | L35: Périodique | M35: Version courante | N35: Carte + tableau | O35: LO 2.0 | P35: National | Q35: Distinguer gares voyageurs, haltes et gares de fret selon ce qu'on veut montrer.
A36: TRA-07 | B36: Transports & mobilité | C36: Arrêts de transport | D36: Point d'Accès National | E36: GTFS (fichier stops) | F36: Extraction GTFS | G36: Arrêt | H36: Natif | I36: Agrégeable | J36: Agrégeable | K36: Comptage | L36: Variable | M36: Version courante | N36: Carte | O36: LO 2.0 / ODbL | P36: Un flux par territoire | Q36: Doublons fréquents entre réseaux se recouvrant : dédoublonner sur la position avant tout comptage.
A37: TRA-08 | B37: Transports & mobilité | C37: Tracés et réseaux de lignes | D37: Point d'Accès National | E37: GTFS (fichier shapes) / NeTEx | F37: Extraction GTFS | G37: Ligne | H37: Natif | I37: Partiel | J37: Agrégeable | K37: Sans objet | L37: Variable | M37: Version courante | N37: Carte | O37: LO 2.0 / ODbL | P37: Un flux par territoire | Q37: Une ligne traverse plusieurs territoires : l'afficher entière plutôt que la découper.
A38: TRA-09 | B38: Transports & mobilité | C38: Horaires de transport | D38: Point d'Accès National | E38: GTFS statique, SIRI pour le temps réel | F38: Fichier / API temps réel | G38: Ligne / arrêt | H38: Natif | I38: Sans objet | J38: Sans objet | K38: Sans objet | L38: Continue | M38: Version courante | N38: Tableau | O38: LO 2.0 / ODbL | P38: Un flux par territoire | Q38: Le temps réel impose une architecture différente (pas d'ETL nocturne). À écarter de l'objectif principal, à traiter en évolution.
A39: TRA-10 | B39: Transports & mobilité | C39: Stationnement | D39: Point d'Accès National / OSM | E39: Base nationale des lieux de stationnement | F39: Fichier / API | G39: Parking | H39: Partiel | I39: Partiel | J39: Partiel | K39: Comptage et somme des capacités | L39: Variable | M39: Version courante | N39: Carte + tableau | O39: LO 2.0 / ODbL | P39: National, couverture variable | Q39: Couverture dépendante du volontariat des collectivités : lacunaire hors grandes agglomérations.
A40: TRA-11 | B40: Transports & mobilité | C40: Bornes de recharge pour véhicules électriques | D40: Etalab / opérateurs | E40: Base nationale des IRVE | F40: Fichier / API | G40: Point de charge | H40: Natif | I40: Agrégeable | J40: Agrégeable | K40: Comptage points et puissance cumulée | L40: Quotidienne | M40: Version courante | N40: Carte + tableau | O40: LO 2.0 | P40: National | Q40: Distinguer station et point de charge : les deux comptages diffèrent fortement. | R40: prévu — carburants
...

Sheet Rattachement categories
A1: Une même donnée peut apparaître dans plusieurs catégories du site. Elle n'est chargée qu'une fois ; seul son rattachement est multiple.
A2: ID donnée | B2: Libellé | C2: Catégorie principale | D2: Catégories secondaires
A3: GEO-05 | B3: Parcelles cadastrales | C3: Géographie & cartographie | D3: Urbanisme & construction
A4: GEO-09 | B4: Équipements publics géolocalisés | C4: Géographie & cartographie | D4: Santé ; Éducation ; Culture & patrimoine ; Administrations & services publics ; Tourisme
A5: GEO-10 | B5: Données géographiques environnementales | C5: Géographie & cartographie | D5: Environnement & climat ; Eau
A6: GEO-11 | B6: Référentiels géographiques socles | C6: Géographie & cartographie | D6: Transports & mobilité ; Urbanisme & construction ; Eau
A7: POP-04 | B7: Naissances | C7: Population & démographie | D7: Santé
A8: POP-05 | B8: Décès | C8: Population & démographie | D8: Santé
A9: POP-13 | B9: Revenus | C9: Population & démographie | D9: Emploi & travail ; Finances publiques & fiscalité
A10: POP-14 | B10: Taux de pauvreté | C10: Population & démographie | D10: Emploi & travail
A11: TRA-01 | B11: Réseau routier | C11: Transports & mobilité | D11: Géographie & cartographie
A12: TRA-11 | B12: Bornes de recharge | C12: Transports & mobilité | D12: Environnement & climat
A13: TRA-12 | B13: Aménagements cyclables | C13: Transports & mobilité | D13: Tourisme ; Environnement & climat
... A21: URB-12 | B21: Risques naturels et technologiques | C21: Urbanisme & construction | D21: Environnement & climat ; Eau ; Industrie & entreprises

Sheet Feuille de route
A1: Les 16 catégories cibles
A3: # | B3: Catégorie | C3: État | D3: Nb de données envisagées | E3: Dépendances / remarque
A4: 1 | B4: Population & démographie | C4: Implantée | D4: 16 | E4: Socle statistique. Conditionne tous les ratios des autres catégories (dénominateurs).
A5: 2 | B5: Géographie & cartographie | C5: Implantée | D5: 12 | E5: À traiter en premier dans le développement : référentiels et géométries dont tout le reste dépend.
A6: 3 | B6: Transports & mobilité | C6: Partielle — équipements hivernaux | D6: 15 | E6: Forte dépendance au Point d'Accès National, un connecteur par autorité organisatrice.
A7: 4 | B7: Urbanisme & construction | C7: Implantée (logement) | D7: 12 | E7: Couverture GPU à vérifier sur la zone avant tout engagement.
A8: 5 | B8: Environnement & climat | C8: À cataloguer | E8: Sources multiples (LCSQA/AASQA, Géorisques, ADEME). Recoupe fortement Eau et Météo.
A9: 6 | B9: Santé | C9: À cataloguer | E9: FINESS pour les établissements, RPPS/annuaire santé pour les professionnels. Peu de maille communale au-delà.
A10: 7 | B10: Éducation | C10: À cataloguer | E10: Annuaire de l'éducation et résultats aux examens : bonne couverture communale.
A11: 8 | B11: Emploi & travail | C11: À cataloguer | E11: Point de difficulté : le chômage est publié en zone d'emploi, pas en commune.
A12: 9 | B12: Politique & démocratie | C12: Partielle — élus faits, résultats à venir | D12: 11 | E12: Seule catégorie nativement cantonale. Structure de données distincte des autres : voir l'onglet Résultats électoraux.
A13: 10 | B13: Finances publiques & fiscalité | C13: À cataloguer | E13: Comptes des collectivités : maille commune et EPCI natives, agrégation à éviter (budgets non additifs).
A14: 11 | B14: Industrie & entreprises | C14: À cataloguer | E14: Sirene, ICPE, registre des émissions polluantes.
A15: 12 | B15: Administrations & services publics | C15: À cataloguer | E15: Largement couvert par la BPE déjà cataloguée (GEO-09) + annuaire de l'administration.
A16: 13 | B16: Culture & patrimoine | C16: À cataloguer | E16: Monuments historiques, musées de France, bibliothèques.
A17: 14 | B17: Tourisme | C17: À cataloguer | E17: Capacités d'hébergement INSEE, classements Atout France.
A18: 15 | B18: Eau | C18: À cataloguer | E18: Hub'Eau (API par thème) et qualité de l'eau potable. Maille = station, pas commune.
A19: 16 | B19: Météo & climat | C19: À cataloguer | E19: Météo-France : maille station. Aucun niveau administratif natif, à requalifier en « station la plus proche ».

Sheet Nomenclature
A1: Valeurs autorisées — à respecter pour l'ajout des 12 catégories restantes
A3: Colonne | B3: Valeur autorisée | C3: Signification
A4: Commune / Canton / EPCI | B4: Natif | C4: La source publie la valeur à ce niveau. Aucun calcul, fiabilité maximale.
A5: Commune / Canton / EPCI | B5: Agrégeable | C5: Effectif : la somme des communes est exacte.
A6: Commune / Canton / EPCI | B6: Recalculé | C6: Taux, moyenne ou densité : refaire le calcul à partir du numérateur et du dénominateur agrégés.
A7: Commune / Canton / EPCI | B7: Reconstitué | C7: Somme possible mais inexacte si le canton contient une commune scindée. Avertissement obligatoire.
A8: Commune / Canton / EPCI | B8: Partiel | C8: Donnée existante mais couverture incomplète du territoire.
A9: Commune / Canton / EPCI | B9: Non | C9: Indisponible ou non calculable à ce niveau. La fiche ne l'affiche pas.
A10: Commune / Canton / EPCI | B10: Sans objet | C10: La notion n'a pas de sens à ce niveau.
A11: Affichage recommandé | B11: Texte | C11: Valeur unique commentée.
A12: Affichage recommandé | B12: Tableau | C12: Plusieurs modalités ou plusieurs années.
A13: Affichage recommandé | B13: Graphique | C13: Évolution, répartition, pyramide.
A14: Affichage recommandé | B14: Carte | C14: Donnée localisée ou comparaison entre territoires.
... A22: Accès technique | B22: WMTS / TMS | C22: Tuiles de fond de carte, consommées directement par le navigateur.

Sheet Synthese
A1: Couverture par niveau
A2: Compteurs automatiques : ils se mettent à jour à mesure que vous complétez l'onglet Catalogue.
A4: Statut | B4: Commune | C4: Canton | D4: EPCI
A5: Natif | B5: =COUNTIF(Catalogue!$H$2:$H$67,$A5) | C5: =COUNTIF(Catalogue!$I$2:$I$67,$A5) | D5: =COUNTIF(Catalogue!$J$2:$J$67,$A5)
A6: Agrégeable | B6: =COUNTIF(Catalogue!$H$2:$H$67,$A6) | C6: =COUNTIF(Catalogue!$I$2:$I$67,$A6) | D6: =COUNTIF(Catalogue!$J$2:$J$67,$A6)
A7: Recalculé | B7: =COUNTIF(Catalogue!$H$2:$H$67,$A7) | C7: =COUNTIF(Catalogue!$I$2:$I$67,$A7) | D7: =COUNTIF(Catalogue!$J$2:$J$67,$A7)
A8: Reconstitué | B8: =COUNTIF(Catalogue!$H$2:$H$67,$A8) | C8: =COUNTIF(Catalogue!$I$2:$I$67,$A8) | D8: =COUNTIF(Catalogue!$J$2:$J$67,$A8)
A9: Partiel | B9: =COUNTIF(Catalogue!$H$2:$H$67,$A9) | C9: =COUNTIF(Catalogue!$I$2:$I$67,$A9) | D9: =COUNTIF(Catalogue!$J$2:$J$67,$A9)
A10: Non | B10: =COUNTIF(Catalogue!$H$2:$H$67,$A10) | C10: =COUNTIF(Catalogue!$I$2:$I$67,$A10) | D10: =COUNTIF(Catalogue!$J$2:$J$67,$A10)
A11: Sans objet | B11: =COUNTIF(Catalogue!$H$2:$H$67,$A11) | C11: =COUNTIF(Catalogue!$I$2:$I$67,$A11) | D11: =COUNTIF(Catalogue!$J$2:$J$67,$A11)
A12: Total | B12: =SUM(B5:B11) | C12: =SUM(C5:C11) | D12: =SUM(D5:D11)
A14: Répartition par catégorie | F14: Passage à l'échelle
A15: Catégorie | B15: Nb de données | F15: Type de source | G15: Nb
A16: Population & démographie | B16: =COUNTIF(Catalogue!$B$2:$B$67,$A16) | F16: National | G16: =COUNTIF(Catalogue!$P$2:$P$67,$F16)
A17: Géographie & cartographie | B17: =COUNTIF(Catalogue!$B$2:$B$67,$A17) | F17: National, couverture variable | G17: =COUNTIF(Catalogue!$P$2:$P$67,$F17)
A18: Transports & mobilité | B18: =COUNTIF(Catalogue!$B$2:$B$67,$A18) | F18: Un flux par territoire | G18: =COUNTIF(Catalogue!$P$2:$P$67,$F18)
A19: Urbanisme & construction | B19: =COUNTIF(Catalogue!$B$2:$B$67,$A19) | F19: Commune par commune | G19: =COUNTIF(Catalogue!$P$2:$P$67,$F19)
A20: Politique & démocratie | B20: =COUNTIF(Catalogue!$B$2:$B$67,$A20)
A21: Total catalogué | B21: =SUM(B16:B20)
A23: État au | B23: 07/09/2026
A24: Données cataloguées | B24: 79
A25: Collecteurs en service | B25: 16
A26: Rubriques ouvertes | B26: 7
A27: Pages produites | B27: environ 480
A28: Catégories couvertes | B28: 7 sur 16

Sheet Résultats électoraux
A1: Résultats électoraux — modèle de données distinct
A2: Les résultats électoraux ne rentrent pas dans la table générique des indicateurs. Ils ont leur propre structure, leur propre maille (le bureau de vote) et leur propre calendrier. Ils partagent en revanche le référentiel de territoires.
A4: 1. Structure des tables
A5: Table | B5: Clés | C5: Contenu | D5: Remarque
A6: scrutin | B6: id_scrutin | C6: Type (présidentielle, législatives, départementales…), date, numéro de tour, libellé. | D6: Un tour = une ligne. Ne jamais fusionner les deux tours dans un même enregistrement.
A7: bureau_vote | B7: id_scrutin + code_commune + code_bv | C7: Libellé, adresse, coordonnées si disponibles. | D7: Rattaché au scrutin et non global : les bureaux sont redécoupés et renumérotés entre deux élections.
A8: participation | B8: id_scrutin + niveau + code | C8: Inscrits, abstentions, votants, blancs, nuls, exprimés. | D8: Effectifs uniquement. Les taux se recalculent à l'affichage, jamais stockés.
A9: resultat | B9: id_scrutin + niveau + code + rang | C9: Nom, prénom, nuance publiée, libellé de liste, voix. | D9: Voix uniquement. Les pourcentages se recalculent sur les exprimés du même enregistrement.
A10: nuance_regroupement | B10: nuance + id_regroupement | C10: Correspondance entre nuances publiées et blocs politiques d'affichage. | D10: Table éditoriale, assumée et datée. C'est un choix de votre part, pas une donnée officielle.
A12: 2. Règles de conception
A13: — Niveau = bureau de vote, commune, canton, EPCI, département, région. Le bureau de vote est un quatrième niveau, propre à l'électoral, qui ne remonte pas dans le reste du modèle.
A14: — Stocker la maille la plus fine publiée, puis agréger. Conserver aussi le total communal publié par le ministère et le comparer à la somme des bureaux : tout écart signale une anomalie d'intégration.
A15: — Stocker la nuance telle que publiée, sans jamais la corriger. Les regroupements en blocs politiques passent par une table à part, modifiable et réversible.
A16: — Ne jamais stocker de pourcentage. Un pourcentage dépend du dénominateur choisi (exprimés ou inscrits) : le figer revient à figer une interprétation.
A17: — Partitionner les fichiers publiés par commune. Un fichier par commune contenant tout son historique reste léger, même à l'échelle régionale, et préserve la génération statique.
A19: 3. Scrutins à intégrer
A20: Disponibilité à vérifier scrutin par scrutin. La maille communale remonte loin ; la maille bureau de vote n'est fiable que pour les scrutins récents.
A21: Scrutin | B21: Années | C21: Maille commune | D21: Maille canton | E21: Priorité
A22: Présidentielle | B22: 2002, 2007, 2012, 2017, 2022 · puis avril-mai 2027 | C22: Oui | D22: Par agrégation | E22: 1 — la plus consultée
A23: Départementales | B23: 2015, 2021 · puis mars 2028 | C23: Oui | D23: Native | E23: 1 — seule maille cantonale
A24: Cantonales (ancien découpage) | B24: 2004, 2008, 2011 | C24: Oui | D24: Incomparable | E24: 4 — cantons différents, hors périmètre cantonal
A25: Législatives | B25: 2002, 2007, 2012, 2017, 2022, 2024 | C25: Oui | D25: Par agrégation | E25: 2
A26: Européennes | B26: 2004, 2009, 2014, 2019, 2024 | C26: Oui | D26: Par agrégation | E26: 2 — la plus comparable dans le temps
A27: Régionales | B27: 2004, 2010, 2015, 2021 · puis mars 2028 | C27: Oui | D27: Par agrégation | E27: 3
A28: Municipales | B28: 2001, 2008, 2014, 2020, 2026 | C28: Oui | D28: Sans objet | E28: 3 — pas d'agrégation possible
A29: Référendum | B29: 2005 | C29: Oui | D29: Par agrégation | E29: 4
A31: 4. Points de vigilance
A32: — Le bureau de vote n'est pas stable dans le temps. Périmètres et numérotations changent entre scrutins, sans référentiel historique national. Conséquence : le détail par bureau se consulte scrutin par scrutin ; les séries chronologiques se font à la commune.
A33: — Les contours géographiques des bureaux de vote ne sont pas publiés partout. Prévoir un affichage en tableau, et n'envisager la carte que si la couverture existe sur le territoire.
A34: — Chaque scrutin ancien a son propre format de fichier. L'intégration est un connecteur par élection, soit une quinzaine de traitements ponctuels. C'est un coût unique : les résultats passés ne changent plus jamais.
A35: — Le redécoupage cantonal de 2015 interdit toute comparaison cantonale antérieure. Les cantonales 2004 à 2011 restent intégrables à la maille communale uniquement.
A36: — Les fusions de communes cassent les séries longues. Appliquer la table de passage du COG avant tout graphique d'évolution.
A37: — Ne jamais comparer deux scrutins de nature différente. Une participation de présidentielle et une participation de départementales ne se lisent pas sur la même échelle.
